<?xml version="1.0" ?>
<robot name="candynamix" xmlns:xacro="http://ros.org/wiki/xacro">
  <xacro:include filename="$(find candynamix_description)/urdf/common_properties.xacro"/>
  <xacro:include filename="$(find candynamix_description)/urdf/candynamix.gazebo.xacro"/>

  <link name="base_footprint"/>

  <joint name="base_joint" type="fixed">
    <parent link="base_footprint"/>
    <child link="base_link"/>
    <origin xyz="0 0 0.0" rpy="0 0 0"/>
  </joint>

  <link name="base_link">
    <visual>
      <origin xyz="-0.0345 0.112 0.077" rpy="0 0 3.14"/>
      <geometry>
        <mesh filename="package://candynamix_description/meshes/bases/candynamix_base.stl" scale="0.001 0.001 0.001"/>
      </geometry>
      <material name="orange"/>
    </visual>

    <collision>
      <origin xyz="-0.0345 0.112 0.077" rpy="0 0 3.14"/>
      <geometry>
        <box size="0.140 0.140 0.140"/>
      </geometry>
    </collision>

    <inertial>
      <origin xyz="-0.0345 0.112 0.077" rpy="0 0 3.14"/>
      <mass value="1"/>
      <inertia ixx="0.01" ixy="0.0" ixz="0.0"
               iyy="0.01" iyz="0.0"
               izz="0.01" />
    </inertial>
  </link>

  <joint name="wheel_left_joint" type="continuous">
    <parent link="base_link"/>
    <child link="wheel_left_link"/>
    <origin xyz="0 0.038 0.016" rpy="${-M_PI*0.5} 1.58 1.58"/>
    <axis xyz="0 1 0"/>
  </joint>
 
  <link name="wheel_left_link">
    <visual>
      <origin xyz="0 0 0" rpy="${-M_PI*0.5} 0 0"/>
      <geometry>
        <mesh filename="package://candynamix_description/meshes/wheels/left_tire.stl" scale="0.001 0.001 0.001"/>
      </geometry>
      <material name="dark"/>
    </visual>

    <collision>
      <origin xyz="0 0 0" rpy="0 0 0"/>
      <geometry>
        <cylinder length="0.018" radius="0.033"/>
      </geometry>
    </collision>

    <inertial>
      <origin xyz="0 0 0" />
      <mass value="0.01" />
      <inertia ixx="0.001" ixy="0.0" ixz="0.0"
               iyy="0.001" iyz="0.0"
               izz="0.001" />
    </inertial>
  </link>

  <joint name="wheel_right_joint" type="continuous">
    <parent link="base_link"/>
    <child link="wheel_right_link"/>
<!-- origin xyz="0 0.036 0.016" rpy="${-M_PI*0.5} 1.58 1.58"/-->
    <origin xyz="0 -0.038 0.016" rpy="${-M_PI*0.5} -1.58 1.58"/>
    <axis xyz="0 1 0"/>
  </joint>

  <link name="wheel_right_link">
    <visual>
      <origin xyz="0 0 0" rpy="${M_PI*0.5} 0 0"/>
      <geometry>
        <mesh filename="package://candynamix_description/meshes/wheels/right_tire.stl" scale="0.001 0.001 0.001"/>
      </geometry>
      <material name="dark"/>
    </visual>

    <collision>
      <origin xyz="0 0 0" rpy="0 0 0"/>
      <geometry>
        <cylinder length="0.018" radius="0.033"/>
      </geometry>
    </collision>

    <inertial>
      <origin xyz="0 0 0" />
      <mass value="0.01" />
      <inertia ixx="0.001" ixy="0.0" ixz="0.0"
               iyy="0.001" iyz="0.0"
               izz="0.001" />
    </inertial>
  </link>

  <joint name="caster_back_joint" type="fixed">
    <parent link="base_link"/>
    <child link="caster_back_link"/>
    <origin xyz="-0.081 0 -0.004" rpy="${-M_PI*0.5} 0 0"/>
  </joint>

  <link name="caster_back_link">
    <collision>
      <origin xyz="0 0 0" rpy="0 0 0"/>
      <geometry>
        <box size="0.030 0.010 0.020"/>
      </geometry>
    </collision>

    <inertial>
      <origin xyz="0 0 0" />
      <mass value="0.01" />
      <inertia ixx="0.001" ixy="0.0" ixz="0.0"
               iyy="0.001" iyz="0.0"
               izz="0.001" />
    </inertial>
  </link>

  <joint name="imu_joint" type="fixed">
    <parent link="base_link"/>
    <child link="imu_link"/>
    <origin xyz="-0.032 0 0.068" rpy="0 0 0"/>
  </joint>

  <link name="imu_link"/>

  <joint name="scan_joint" type="fixed">
    <parent link="base_link"/>
    <child link="base_scan"/>
    <origin xyz="-0.032 0 0.171" rpy="0 0 0"/>
  </joint>


  <link name="base_scan">
<!--
    <visual>
      <origin xyz="0 0 0.0" rpy="0 0 0"/>
      <geometry>
        <mesh filename="package://candynamix/candynamix_description/meshes/sensors/lds.stl" scale="0.001 0.001 0.001"/>
      </geometry>
      <material name="dark"/>
    </visual>

    <collision>
      <origin xyz="0 0 0" rpy="0 0 0"/>
      <geometry>
        <cylinder length="0.0408" radius="0.070"/>
      </geometry>
    </collision>

    <inertial>
      <mass value="0.01" />
      <origin xyz="0 0 0" />
      <inertia ixx="0.001" ixy="0.0" ixz="0.0"
               iyy="0.001" iyz="0.0"
               izz="0.001" />
    </inertial>
-->
  </link>

</robot>

